Workbook

Sheet Data Input
A1: # | B1: Song | C1: Artist | D1: Popularity | E1: BPM | F1: Genres | G1: Album | H1: Album Date | I1: Time | J1: Dance | K1: Energy | L1: Acoustic | M1: Instrumental | N1: Happy | O1: Speech | P1: Live | Q1: Loud (Db) | R1: Key | S1: Time Signature | T1: Added At | U1: Spotify Track Id | V1: Camelot | W1: ISRC
A2: 1 | B2: Somebody Made For Me | C2: Emitt Rhodes | D2: 47 | E2: 179 | F2: baroque pop, power pop | G2: The Emitt Rhodes Recordings (1969-1973) | H2: 40008 | I2: 0.10138889 | J2: 31 | K2: 52 | L2: 10 | M2: 0 | N2: 61 | O2: 0 | P2: 0 | Q2: -8 | R2: G#/A♭ Major | S2: 4 | T2: 45880 | U2: 2hq50hCUUknhUXZ9uL3wgq | V2: 4B | W2: USMC17054041
A3: 2 | B3: You're A Song (That I Can't Sing) | C3: Frankie Valli & The Four Seasons | D3: 33 | E3: 78 | F3: doo-wop, northern soul, motown | G3: Chameleon | H3: 26420 | I3: 0.13263889 | J3: 50 | K3: 56 | L3: 18 | M3: 0 | N3: 64 | O3: 0 | P3: 0 | Q3: -9 | R3: C Minor | S3: 4 | T3: 45880 | U3: 5ZXxJ5AWzZ6Td3MZKbwwdt | V3: 5A | W3: USUM70813531
A4: 3 | B4: Always See Your Face | C4: Love | D4: 51 | E4: 110 | F4: psychedelic rock, acid rock, baroque pop, proto-punk | G4: Four Sail (Expanded Edition) | H4: 25447 | I4: 0.14513889 | J4: 57 | K4: 58 | L4: 38 | M4: 0 | N4: 92 | O4: 0 | P4: 0 | Q4: -13 | R4: C Major | S4: 4 | T4: 45880 | U4: 6OojY4NdPiEGWHV2EUSwHz | V4: 8B | W4: USEE10182644
A5: 4 | B5: When Your Parents Go to Sleep - 2003 Remaster | C5: Kevin Ayers | D5: 32 | E5: 142 | F5: progressive rock, art rock, krautrock, psychedelic rock | G5: Bananamour | H5: 1973-00-00 | I5: 0.24097222 | J5: 53 | K5: 38 | L5: 15 | M5: 0 | N5: 59 | O5: 0 | P5: 10 | Q5: -9 | R5: C Major | S5: 3 | T5: 45880 | U5: 5HUFcB9PHfVcvXF44u98SI | V5: 8B | W5: GBAYE0300437
A6: 5 | B6: Mucho Mungo / Mt. Elga | C6: Harry Nilsson | D6: 33 | E6: 116 | F6: baroque pop, singer-songwriter | G6: Pussy Cats | H6: 27260 | I6: 0.15833333 | J6: 65 | K6: 52 | L6: 31 | M6: 30 | N6: 57 | O6: 0 | P6: 0 | Q6: -11 | R6: D Major | S6: 4 | T6: 45880 | U6: 1xcJNBxc4MYFEN6UoE2HUY | V6: 10B | W6: USRC17402438
A7: 6 | B7: Be Thankful for What You Got | C7: Love | D7: 44 | E7: 99 | F7: psychedelic rock, acid rock, baroque pop, proto-punk | G7: Reel to Real (Deluxe Version) | H7: 42335 | I7: 0.18958333 | J7: 68 | K7: 59 | L7: 65 | M7: 4 | N7: 62 | O7: 20 | P7: 0 | Q7: -12 | R7: B Minor | S7: 4 | T7: 45880 | U7: 1twhAK1Iu5eZYzFrH2LC8P | V7: 10A | W7: QMEF91350058
A8: 7 | B8: Ruler Of My Heart | C8: Irma Thomas | D8: 45 | E8: 94 | F8: classic soul | G8: Irma Thomas Collection: 1961-1966 | H8: 35065 | I8: 0.11041667 | J8: 61 | K8: 28 | L8: 86 | M8: 28 | N8: 47 | O8: 0 | P8: 10 | Q8: -14 | R8: A Major | S8: 3 | T8: 45880 | U8: 2W9cyvOHeC26mSy96802Kk | V8: 11B | W8: USEM39400180
A9: 8 | B9: Wish I Had Not Said That | C9: J.J. Cale | D9: 43 | E9: 90 | F9: blues, blues rock, roots rock | G9: Shades | H9: 29618 | I9: 0.14027778 | J9: 82 | K9: 22 | L9: 68 | M9: 19 | N9: 71 | O9: 0 | P9: 10 | Q9: -17 | R9: C Major | S9: 4 | T9: 45880 | U9: 21xRayzq2plVwcnONznLiy | V9: 8B | W9: NLF050290053
A10: 9 | B10: Sycamore | C10: Bill Callahan | D10: 42 | E10: 120 | F10: alt country | G10: Woke On A Whaleheart | H10: 39196 | I10: 0.23263889 | J10: 66 | K10: 75 | L10: 11 | M10: 0 | N10: 77 | O10: 0 | P10: 10 | Q10: -6 | R10: B Major | S10: 4 | T10: 45880 | U10: 0do3zfmbVl5DiGxUXrbhrT | V10: 1B | W10: US58L0733204
A11: 10 | B11: Aretha, Sing One for Me | C11: George Jackson | D11: 40 | E11: 86 | F11: northern soul, soul | G11: The Blues Sessions | H11: 42705 | I11: 0.12291667 | J11: 69 | K11: 34 | L11: 80 | M11: 1 | N11: 61 | O11: 0 | P11: 10 | Q11: -11 | R11: C Major | S11: 4 | T11: 45880 | U11: 37YeLdDc63BahWGwCaViTB | V11: 8B | W11: US2HK1330630
A12: 11 | B12: You've Got a Woman | C12: Lion | D12: 57 | E12: 144 | G12: You've Got a Woman | H12: 27395 | I12: 0.14236111 | J12: 72 | K12: 86 | L12: 29 | M12: 0 | N12: 97 | O12: 0 | P12: 0 | Q12: -7 | R12: F#/G♭ Minor | S12: 4 | T12: 45880 | U12: 6G6mulVvHFpJsnoKASUPYP | V12: 11A | W12: USCW61706301
A13: 12 | B13: I Love Hot Nights | C13: Jonathan Richman,The Modern Lovers | D13: 39 | E13: 112 | F13: proto-punk, anti-folk | G13: Modern Lovers 88 | H13: 1987-00-00 | I13: 0.12291667 | J13: 71 | K13: 61 | L13: 59 | M13: 0 | N13: 85 | O13: 0 | P13: 0 | Q13: -12 | R13: F Major | S13: 4 | T13: 45880 | U13: 7xqwxkdMnYCcEegCtFfbK5 | V13: 7B | W13: USC4R2111532
A14: 13 | B14: Girl from the Mountain | C14: Ghetto Brothers | D14: 31 | E14: 123 | G14: Power Fuerza | H14: 1972-00-00 | I14: 0.18333333 | J14: 47 | K14: 68 | L14: 28 | M14: 0 | N14: 87 | O14: 0 | P14: 0 | Q14: -9 | R14: A#/B♭ Minor | S14: 4 | T14: 45880 | U14: 5d0Ga3ZvRUD9hdLv189r1A | V14: 3A | W14: QM6P41449831
A15: 14 | B15: Can't Nobody Love You | C15: The Zombies | D15: 41 | E15: 102 | F15: baroque pop, psychedelic rock | G15: Begin Here | H15: 23862 | I15: 0.094444444 | J15: 45 | K15: 41 | L15: 76 | M15: 0 | N15: 58 | O15: 0 | P15: 20 | Q15: -9 | R15: C Major | S15: 3 | T15: 45880 | U15: 0sbBYPII5ZMditx4u3vodY | V15: 8B | W15: GBCBS6432200
A16: 15 | B16: Till The Moon Don’t Shine | C16: Female Species | D16: 37 | E16: 84 | F16: psychedelic rock | G16: Tale Of My Lost Love | H16: 44295 | I16: 0.12013889 | J16: 57 | K16: 27 | L16: 14 | M16: 0 | N16: 48 | O16: 0 | P16: 0 | Q16: -13 | R16: C♯/D♭ Major | S16: 4 | T16: 45880 | U16: 4zkSbeukT3yk4mKvmUhkqg | V16: 3B | W16: USCW62107314
A17: 16 | B17: Wichita Lineman | C17: The Meters | D17: 35 | E17: 83 | F17: funk, soul, jazz funk | G17: Struttin' | H17: 1970-00-00 | I17: 0.12430556 | J17: 54 | K17: 34 | L17: 21 | M17: 1 | N17: 35 | O17: 0 | P17: 20 | Q17: -15 | R17: D Minor | S17: 4 | T17: 45880 | U17: 3EgkmxKS8IN08vbdoL7cFi | V17: 7A | W17: USRH10164885
A18: 17 | B18: I Don't Care | C18: Final Solution | D18: 35 | E18: 94 | G18: Brotherman: OST by The Final Solution | H18: 39672 | I18: 0.17847222 | J18: 47 | K18: 73 | L18: 24 | M18: 0 | N18: 61 | O18: 0 | P18: 0 | Q18: -7 | R18: E Minor | S18: 4 | T18: 45880 | U18: 6ws2EQ5IRAc2N874bKSIBm | V18: 9A | W18: USCW60802203
A19: 18 | B19: Sister, Brother | C19: F. J. McMahon | D19: 45 | E19: 94 | G19: Spirit of the Golden Juice | H19: 43888 | I19: 0.17083333 | J19: 67 | K19: 51 | L19: 63 | M19: 10 | N19: 65 | O19: 0 | P19: 0 | Q19: -12 | R19: A Minor | S19: 4 | T19: 45880 | U19: 1NH6FdQ8V0Idg0UK5v9w7R | V19: 8A | W19: QMV8L1604601
A20: 19 | B20: Fine Street Woman | C20: Kathy Heideman | D20: 29 | E20: 87 | G20: Move With Love | H20: 41548 | I20: 0.18680556 | J20: 51 | K20: 42 | L20: 50 | M20: 0 | N20: 58 | O20: 0 | P20: 20 | Q20: -11 | R20: B Minor | S20: 4 | T20: 45880 | U20: 4o2UB9Fc01g6RQLiP644f0 | V20: 10A | W20: USCW61300119
A21: 20 | B21: Get Thy Bearings | C21: Donovan | D21: 44 | E21: 76 | F21: folk rock, psychedelic rock | G21: The Hurdy Gurdy Man | H21: 25112 | I21: 0.11527778 | J21: 57 | K21: 27 | L21: 38 | M21: 49 | N21: 56 | O21: 0 | P21: 10 | Q21: -17 | R21: E Minor | S21: 4 | T21: 45880 | U21: 6poYscuLQG8hvpxNnyeMUV | V21: 9A | W21: USSM19912401
A22: 21 | B22: No Other | C22: Gene Clark | D22: 41 | E22: 97 | F22: country rock, baroque pop, folk rock, americana | G22: No Other | H22: 27273 | I22: 0.21388889 | J22: 47 | K22: 62 | L22: 42 | M22: 72 | N22: 55 | O22: 0 | P22: 10 | Q22: -14 | R22: D Major | S22: 4 | T22: 45880 | U22: 6gzhmgjSvFuwTLc6XyRv2Q | V22: 10B | W22: USEE10251076
A23: 22 | B23: Forever | C23: Pete Drake | D23: 31 | E23: 102 | G23: Steel Funk | H23: 22268 | I23: 0.11180556 | J23: 61 | K23: 31 | L23: 47 | M23: 46 | N23: 59 | O23: 0 | P23: 10 | Q23: -13 | R23: C Major | S23: 3 | T23: 45880 | U23: 4tLRRQdI6QyPdCU9m2uBTi | V23: 8B | W23: DEXO52469239
A24: 23 | B24: I Am Controlled By Your Love | C24: Helene Smith | D24: 40 | E24: 79 | F24: northern soul, classic soul | G24: I Am Controlled By Your Love | H24: 45079 | I24: 0.12986111 | J24: 58 | K24: 48 | L24: 18 | M24: 3 | N24: 46 | O24: 0 | P24: 10 | Q24: -7 | R24: B Minor | S24: 4 | T24: 45880 | U24: 5QeUAekmZn2nyiBzW5cUUv | V24: 10A | W24: USCW60600703
A25: 24 | B25: Synthetic World | C25: Swamp Dogg | D25: 36 | E25: 89 | F25: retro soul | G25: The Excellent Sides of Swamp Dogg Vol. 1 | H25: 39542 | I25: 0.14236111 | J25: 79 | K25: 34 | L25: 14 | M25: 1 | N25: 88 | O25: 0 | P25: 10 | Q25: -16 | R25: A#/B♭ Major | S25: 4 | T25: 45880 | U25: 2SzN8aFto8qDLdA9Lj0txB | V25: 6B | W25: USLN70810710
A26: 25 | B26: Anemone | C26: The Brian Jonestown Massacre | D26: 62 | E26: 83 | F26: neo-psychedelic, shoegaze, psychedelic rock, space rock | G26: Their Satanic Majesties' Second Request | H26: 39608 | I26: 0.23194444 | J26: 53 | K26: 64 | L26: 6 | M26: 84 | N26: 61 | O26: 0 | P26: 20 | Q26: -13 | R26: F Minor | S26: 4 | T26: 45880 | U26: 70WSr32oW4jC1na5I0j0D6 | V26: 4A | W26: GBSLX0810071
A27: 26 | B27: One Evening | C27: Feist | D27: 59 | E27: 112 | G27: Let It Die | H27: 37987 | I27: 0.15 | J27: 96 | K27: 38 | L27: 13 | M27: 0 | N27: 63 | O27: 0 | P27: 0 | Q27: -10 | R27: C Minor | S27: 4 | T27: 45880 | U27: 09dYenMs0WXWh0pAAtd9Zd | V27: 5A | W27: FRZ020302450
A28: 27 | B28: The Magician | C28: Andy Shauf | D28: 49 | E28: 135 | G28: The Party | H28: 42510 | I28: 0.16041667 | J28: 57 | K28: 33 | L28: 38 | M28: 0 | N28: 23 | O28: 0 | P28: 10 | Q28: -9 | R28: A Major | S28: 4 | T28: 45880 | U28: 3dsd09qrt34YuS6NPbQtYq | V28: 11B | W28: USEP41541003
A29: 28 | B29: Diving Woman | C29: Japanese Breakfast | D29: 49 | E29: 120 | G29: Soft Sounds from Another Planet | H29: 42930 | I29: 0.27222222 | J29: 46 | K29: 75 | L29: 0 | M29: 63 | N29: 26 | O29: 0 | P29: 10 | Q29: -7 | R29: E Major | S29: 4 | T29: 45880 | U29: 6V7c8Dd40BKFqWIYS5zTXx | V29: 12B | W29: USJ5G1713301
A30: 29 | B30: The Conservation of Energy | C30: Vanishing Twin | D30: 36 | E30: 92 | F30: neo-psychedelic | G30: Choose Your Own Adventure | H30: 42643 | I30: 0.17569444 | J30: 47 | K30: 64 | L30: 5 | M30: 61 | N30: 26 | O30: 0 | P30: 10 | Q30: -6 | R30: G Major | S30: 4 | T30: 45880 | U30: 301Xkz1BXL7ve3gl9tRWRM | V30: 9B | W30: GBUQH1500185
A31: 30 | B31: Low Sun | C31: Hermanos Gutiérrez | D31: 67 | E31: 98 | G31: Sonido Cósmico | H31: 45457 | I31: 0.13055556 | J31: 63 | K31: 48 | L31: 90 | M31: 90 | N31: 45 | O31: 0 | P31: 10 | Q31: -11 | R31: E Minor | S31: 3 | T31: 45880 | U31: 1siRw9E67ouBWsORObDuhZ | V31: 9A | W31: USC4R2441425
A32: 31 | B32: Catamaran | C32: Allah-Las | D32: 56 | E32: 122 | F32: surf rock, neo-psychedelic, psychedelic rock | G32: Allah-Las | H32: 41210 | I32: 0.14722222 | J32: 56 | K32: 85 | L32: 1 | M32: 0 | N32: 70 | O32: 0 | P32: 0 | Q32: -6 | R32: E Minor | S32: 4 | T32: 45880 | U32: 4H0KLsPpr5atperrHGfz3x | V32: 9A | W32: USD8D2007001
A33: 32 | B33: Any Other Way | C33: Jackie Shane | D33: 38 | E33: 106 | F33: northern soul | G33: Any Other Way / Sticks And Stones | H33: 23012 | I33: 0.10694444 | J33: 53 | K33: 45 | L33: 69 | M33: 0 | N33: 54 | O33: 0 | P33: 0 | Q33: -6 | R33: C♯/D♭ Major | S33: 4 | T33: 45880 | U33: 5dtUOwEmnDAzsdodWJk4DA | V33: 3B | W33: USUM71518405
A34: 33 | B34: Video Life | C34: Chris Spedding | D34: 42 | E34: 68 | F34: rockabilly, glam rock | G34: Guitar Graffiti (Expanded Edition) | H34: 28491 | I34: 0.13333333 | J34: 53 | K34: 68 | L34: 16 | M34: 0 | N34: 64 | O34: 0 | P34: 60 | Q34: -6 | R34: E Major | S34: 4 | T34: 45880 | U34: 64bWAl2OJFilKBf8bl5rXx | V34: 12B | W34: GBAYE7900156
A35: 34 | B35: Biological Speculation | C35: Funkadelic | D35: 45 | E35: 148 | F35: funk rock, funk | G35: America Eats Its Young | H35: 26441 | I35: 0.12847222 | J35: 58 | K35: 51 | L35: 54 | M35: 0 | N35: 82 | O35: 0 | P35: 10 | Q35: -12 | R35: F Minor | S35: 4 | T35: 45880 | U35: 1S4igP7OpCUIEC5l75DssU | V35: 4A | W35: US25X0588966
A36: 35 | B36: Everybody's Talkin' - From Midnight Cowboy | C36: Harry Nilsson | D36: 67 | E36: 125 | F36: baroque pop, singer-songwriter | G36: Aerial Ballet | H36: 25020 | I36: 0.11319444 | J36: 44 | K36: 35 | L36: 34 | M36: 0 | N36: 68 | O36: 0 | P36: 40 | Q36: -16 | R36: E Major | S36: 4 | T36: 45880 | U36: 1jcPcDu2YawPfLhwjYnqK2 | V36: 12B | W36: USRC19901102
A37: 36 | B37: Under the Boardwalk | C37: The Drifters | D37: 70 | E37: 124 | F37: doo-wop, motown | G37: Under the Boardwalk | H37: 23529 | I37: 0.11180556 | J37: 75 | K37: 23 | L37: 91 | M37: 0 | N37: 78 | O37: 0 | P37: 10 | Q37: -14 | R37: G Major | S37: 4 | T37: 45880 | U37: 65jrjEhWfAvysKfnojk1i0 | V37: 9B | W37: USAT20001017
A38: 37 | B38: Sister Golden Hair | C38: America | D38: 78 | E38: 135 | F38: yacht rock, soft rock, folk rock | G38: Hearts | H38: 1975-00-00 | I38: 0.13819444 | J38: 44 | K38: 55 | L38: 13 | M38: 0 | N38: 72 | O38: 0 | P38: 10 | Q38: -12 | R38: E Major | S38: 4 | T38: 45880 | U38: 5VSAonaAPhhGn0G7hMYwWK | V38: 12B | W38: USWB19901801
A39: 38 | B39: It's Too Late | C39: Carole King | D39: 75 | E39: 208 | F39: singer-songwriter, folk rock | G39: Tapestry | H39: 1971-00-00 | I39: 0.16180556 | J39: 45 | K39: 44 | L39: 49 | M39: 1 | N39: 81 | O39: 0 | P39: 10 | Q39: -13 | R39: A Minor | S39: 4 | T39: 45880 | U39: 12q3V8ShACq2PSWINMc2rC | V39: 8A | W39: USSM17100509
A40: 39 | B40: Peaceful Easy Feeling - 2013 Remaster | C40: Eagles | D40: 70 | E40: 143 | F40: classic rock, yacht rock, soft rock | G40: Eagles (2013 Remaster) | H40: 26451 | I40: 0.17847222 | J40: 57 | K40: 63 | L40: 49 | M40: 0 | N40: 87 | O40: 0 | P40: 20 | Q40: -12 | R40: E Major | S40: 4 | T40: 45880 | U40: 40h65HAR8COEoqkMwUUQHu | V40: 12B | W40: USEE11300322
...

Sheet Data Output
A1: Artist | B1: Name | C1: Energy | D1: BPM | E1: Subgenre | F1: ISRC | G1: AI Generated Energy Score | H1: AI Generated Energy Tag | I1: AI Generated Energy Flag | J1: Human Energy Score | K1: In Cache/New | L1: Feedback | M1: Comments
A2: ='Data Input'!C2 -> Emitt Rhodes | B2: ='Data Input'!B2 -> Somebody Made For Me | C2: =IF(J2="","",IF(J2<=2,"Very Low",IF(J2<=4,"Low",IF(J2<=6,"Medium",IF(J2<=8,"High","Very High"))))) | D2: =ROUND(LET(value,'Data Input'!E2,IF(value>140,value/2,value)),0) -> 90 | F2: ='Data Input'!W2 -> USMC17054041 | G2: 5 | H2: Medium | I2: None | K2: From Cache
A3: ='Data Input'!C3 -> Frankie Valli & The Four Seasons | B3: ='Data Input'!B3 -> You're A Song (That I Can't Sing) | C3: =IF(J3="","",IF(J3<=2,"Very Low",IF(J3<=4,"Low",IF(J3<=6,"Medium",IF(J3<=8,"High","Very High"))))) | D3: =ROUND(LET(value,'Data Input'!E3,IF(value>140,value/2,value)),0) -> 78 | F3: ='Data Input'!W3 -> USUM70813531 | G3: 5 | H3: Medium | I3: None | K3: From Cache
A4: ='Data Input'!C4 -> Love | B4: ='Data Input'!B4 -> Always See Your Face | C4: =IF(J4="","",IF(J4<=2,"Very Low",IF(J4<=4,"Low",IF(J4<=6,"Medium",IF(J4<=8,"High","Very High"))))) | D4: =ROUND(LET(value,'Data Input'!E4,IF(value>140,value/2,value)),0) -> 110 | F4: ='Data Input'!W4 -> USEE10182644 | G4: 4 | H4: Low | I4: None | K4: From Cache
A5: ='Data Input'!C5 -> Kevin Ayers | B5: ='Data Input'!B5 -> When Your Parents Go to Sleep - 2003 Remaster | C5: =IF(J5="","",IF(J5<=2,"Very Low",IF(J5<=4,"Low",IF(J5<=6,"Medium",IF(J5<=8,"High","Very High"))))) | D5: =ROUND(LET(value,'Data Input'!E5,IF(value>140,value/2,value)),0) -> 71 | F5: ='Data Input'!W5 -> GBAYE0300437 | G5: 3 | H5: Low | I5: None | K5: From Cache
A6: ='Data Input'!C6 -> Harry Nilsson | B6: ='Data Input'!B6 -> Mucho Mungo / Mt. Elga | C6: =IF(J6="","",IF(J6<=2,"Very Low",IF(J6<=4,"Low",IF(J6<=6,"Medium",IF(J6<=8,"High","Very High"))))) | D6: =ROUND(LET(value,'Data Input'!E6,IF(value>140,value/2,value)),0) -> 116 | F6: ='Data Input'!W6 -> USRC17402438 | G6: 3 | H6: Low | I6: None | K6: From Cache
A7: ='Data Input'!C7 -> Love | B7: ='Data Input'!B7 -> Be Thankful for What You Got | C7: =IF(J7="","",IF(J7<=2,"Very Low",IF(J7<=4,"Low",IF(J7<=6,"Medium",IF(J7<=8,"High","Very High"))))) | D7: =ROUND(LET(value,'Data Input'!E7,IF(value>140,value/2,value)),0) -> 99 | F7: ='Data Input'!W7 -> QMEF91350058 | G7: 5 | H7: Medium | I7: Groove | K7: From Cache
A8: ='Data Input'!C8 -> Irma Thomas | B8: ='Data Input'!B8 -> Ruler Of My Heart | C8: =IF(J8="","",IF(J8<=2,"Very Low",IF(J8<=4,"Low",IF(J8<=6,"Medium",IF(J8<=8,"High","Very High"))))) | D8: =ROUND(LET(value,'Data Input'!E8,IF(value>140,value/2,value)),0) -> 94 | F8: ='Data Input'!W8 -> USEM39400180 | G8: 7 | H8: High | I8: Dynamic, Groove | K8: From Cache
A9: ='Data Input'!C9 -> J.J. Cale | B9: ='Data Input'!B9 -> Wish I Had Not Said That | C9: =IF(J9="","",IF(J9<=2,"Very Low",IF(J9<=4,"Low",IF(J9<=6,"Medium",IF(J9<=8,"High","Very High"))))) | D9: =ROUND(LET(value,'Data Input'!E9,IF(value>140,value/2,value)),0) -> 90 | F9: ='Data Input'!W9 -> NLF050290053 | G9: 4 | H9: Low | I9: None | K9: From Cache
A10: ='Data Input'!C10 -> Bill Callahan | B10: ='Data Input'!B10 -> Sycamore | C10: =IF(J10="","",IF(J10<=2,"Very Low",IF(J10<=4,"Low",IF(J10<=6,"Medium",IF(J10<=8,"High","Very High"))))) | D10: =ROUND(LET(value,'Data Input'!E10,IF(value>140,value/2,value)),0) -> 120 | F10: ='Data Input'!W10 -> US58L0733204 | G10: 3 | H10: Low | I10: None | K10: From Cache
A11: ='Data Input'!C11 -> George Jackson | B11: ='Data Input'!B11 -> Aretha, Sing One for Me | C11: =IF(J11="","",IF(J11<=2,"Very Low",IF(J11<=4,"Low",IF(J11<=6,"Medium",IF(J11<=8,"High","Very High"))))) | D11: =ROUND(LET(value,'Data Input'!E11,IF(value>140,value/2,value)),0) -> 86 | F11: ='Data Input'!W11 -> US2HK1330630 | G11: 5 | H11: Medium | I11: Groove | K11: From Cache
A12: ='Data Input'!C12 -> Lion | B12: ='Data Input'!B12 -> You've Got a Woman | C12: =IF(J12="","",IF(J12<=2,"Very Low",IF(J12<=4,"Low",IF(J12<=6,"Medium",IF(J12<=8,"High","Very High"))))) | D12: =ROUND(LET(value,'Data Input'!E12,IF(value>140,value/2,value)),0) -> 72 | F12: ='Data Input'!W12 -> USCW61706301 | G12: 4 | H12: Low | I12: None | K12: From Cache
A13: ='Data Input'!C13 -> Jonathan Richman,The Modern Lovers | B13: ='Data Input'!B13 -> I Love Hot Nights | C13: =IF(J13="","",IF(J13<=2,"Very Low",IF(J13<=4,"Low",IF(J13<=6,"Medium",IF(J13<=8,"High","Very High"))))) | D13: =ROUND(LET(value,'Data Input'!E13,IF(value>140,value/2,value)),0) -> 112 | F13: ='Data Input'!W13 -> USC4R2111532 | G13: 4 | H13: Low | I13: None | K13: From Cache
... A122: ='Data Input'!C122 -> The Dramatics | B122: ='Data Input'!B122 -> Whatcha See Is Whatcha Get | C122: =IF(J122="","",IF(J122<=2,"Very Low",IF(J122<=4,"Low",IF(J122<=6,"Medium",IF(J122<=8,"High","Very High"))))) | D122: =ROUND(LET(value,'Data Input'!E122,IF(value>140,value/2,value)),0) -> 77 | F122: ='Data Input'!W122 -> USC4R1100182 | G122: 7 | H122: High | I122: Dynamic, Groove | K122: New
A123: ='Data Input'!C123 | B123: ='Data Input'!B123 | C123: =IF(J123="","",IF(J123<=2,"Very Low",IF(J123<=4,"Low",IF(J123<=6,"Medium",IF(J123<=8,"High","Very High"))))) | D123: =ROUND(LET(value,'Data Input'!E123,IF(value>140,value/2,value)),0) -> 0 | F123: ='Data Input'!W123
A124: ='Data Input'!C124 | B124: ='Data Input'!B124 | C124: =IF(J124="","",IF(J124<=2,"Very Low",IF(J124<=4,"Low",IF(J124<=6,"Medium",IF(J124<=8,"High","Very High"))))) | D124: =ROUND(LET(value,'Data Input'!E124,IF(value>140,value/2,value)),0) -> 0 | F124: ='Data Input'!W124
A125: ='Data Input'!C125 | B125: ='Data Input'!B125 | C125: =IF(J125="","",IF(J125<=2,"Very Low",IF(J125<=4,"Low",IF(J125<=6,"Medium",IF(J125<=8,"High","Very High"))))) | D125: =ROUND(LET(value,'Data Input'!E125,IF(value>140,value/2,value)),0) -> 0 | F125: ='Data Input'!W125
A126: ='Data Input'!C126 | B126: ='Data Input'!B126 | C126: =IF(J126="","",IF(J126<=2,"Very Low",IF(J126<=4,"Low",IF(J126<=6,"Medium",IF(J126<=8,"High","Very High"))))) | D126: =ROUND(LET(value,'Data Input'!E126,IF(value>140,value/2,value)),0) -> 0 | F126: ='Data Input'!W126
A127: ='Data Input'!C127 | B127: ='Data Input'!B127 | C127: =IF(J127="","",IF(J127<=2,"Very Low",IF(J127<=4,"Low",IF(J127<=6,"Medium",IF(J127<=8,"High","Very High"))))) | D127: =ROUND(LET(value,'Data Input'!E127,IF(value>140,value/2,value)),0) -> 0 | F127: ='Data Input'!W127
A128: ='Data Input'!C128 | B128: ='Data Input'!B128 | C128: =IF(J128="","",IF(J128<=2,"Very Low",IF(J128<=4,"Low",IF(J128<=6,"Medium",IF(J128<=8,"High","Very High"))))) | D128: =ROUND(LET(value,'Data Input'!E128,IF(value>140,value/2,value)),0) -> 0 | F128: ='Data Input'!W128
A129: ='Data Input'!C129 | B129: ='Data Input'!B129 | C129: =IF(J129="","",IF(J129<=2,"Very Low",IF(J129<=4,"Low",IF(J129<=6,"Medium",IF(J129<=8,"High","Very High"))))) | D129: =ROUND(LET(value,'Data Input'!E129,IF(value>140,value/2,value)),0) -> 0 | F129: ='Data Input'!W129
A130: ='Data Input'!C130 | B130: ='Data Input'!B130 | C130: =IF(J130="","",IF(J130<=2,"Very Low",IF(J130<=4,"Low",IF(J130<=6,"Medium",IF(J130<=8,"High","Very High"))))) | D130: =ROUND(LET(value,'Data Input'!E130,IF(value>140,value/2,value)),0) -> 0 | F130: ='Data Input'!W130
A131: ='Data Input'!C131 | B131: ='Data Input'!B131 | C131: =IF(J131="","",IF(J131<=2,"Very Low",IF(J131<=4,"Low",IF(J131<=6,"Medium",IF(J131<=8,"High","Very High"))))) | D131: =ROUND(LET(value,'Data Input'!E131,IF(value>140,value/2,value)),0) -> 0 | F131: ='Data Input'!W131
A132: ='Data Input'!C132 | B132: ='Data Input'!B132 | C132: =IF(J132="","",IF(J132<=2,"Very Low",IF(J132<=4,"Low",IF(J132<=6,"Medium",IF(J132<=8,"High","Very High"))))) | D132: =ROUND(LET(value,'Data Input'!E132,IF(value>140,value/2,value)),0) -> 0 | F132: ='Data Input'!W132
A133: ='Data Input'!C133 | B133: ='Data Input'!B133 | C133: =IF(J133="","",IF(J133<=2,"Very Low",IF(J133<=4,"Low",IF(J133<=6,"Medium",IF(J133<=8,"High","Very High"))))) | D133: =ROUND(LET(value,'Data Input'!E133,IF(value>140,value/2,value)),0) -> 0 | F133: ='Data Input'!W133
A134: ='Data Input'!C134 | B134: ='Data Input'!B134 | C134: =IF(J134="","",IF(J134<=2,"Very Low",IF(J134<=4,"Low",IF(J134<=6,"Medium",IF(J134<=8,"High","Very High"))))) | D134: =ROUND(LET(value,'Data Input'!E134,IF(value>140,value/2,value)),0) -> 0 | F134: ='Data Input'!W134
... A816: ='Data Input'!C816 | B816: ='Data Input'!B816 | C816: =IF(J816="","",IF(J816<=2,"Very Low",IF(J816<=4,"Low",IF(J816<=6,"Medium",IF(J816<=8,"High","Very High"))))) | D816: =ROUND(LET(value,'Data Input'!E816,IF(value>140,value/2,value)),0) -> 0 | F816: ='Data Input'!W816

Sheet Feedback Options
A1: Aggressive (All)
A2: Aggressive (Vocals)
A3: Ballad-Like
A4: Curation Quality is Poor
A5: Dark, Broody Track
A6: Dated Track
A7: Energy is high
A8: Energy is low
A9: Good Track
A10: Great Track
A11: Lacks Accessibility/Too Eclectic
A12: Not smooth and steady
... A18: Need Clean Version

Sheet DATA EXPORT
A1: Artist | B1: Name | C1: Energy | D1: BPM | E1: Subgenre | F1: ISRC
A2: ='Data Input'!C2 -> Emitt Rhodes | B2: ='Data Input'!B2 -> Somebody Made For Me | C2: ='Data Output'!C2 | D2: =ROUND(LET(value,'Data Input'!E2,IF(value>140,value/2,value)),0) -> 90 | E2: ='Data Output'!E2 | F2: ='Data Input'!W2 -> USMC17054041
A3: ='Data Input'!C3 -> Frankie Valli & The Four Seasons | B3: ='Data Input'!B3 -> You're A Song (That I Can't Sing) | C3: ='Data Output'!C3 | D3: =ROUND(LET(value,'Data Input'!E3,IF(value>140,value/2,value)),0) -> 78 | E3: ='Data Output'!E3 | F3: ='Data Input'!W3 -> USUM70813531
A4: ='Data Input'!C4 -> Love | B4: ='Data Input'!B4 -> Always See Your Face | C4: ='Data Output'!C4 | D4: =ROUND(LET(value,'Data Input'!E4,IF(value>140,value/2,value)),0) -> 110 | E4: ='Data Output'!E4 | F4: ='Data Input'!W4 -> USEE10182644
A5: ='Data Input'!C5 -> Kevin Ayers | B5: ='Data Input'!B5 -> When Your Parents Go to Sleep - 2003 Remaster | C5: ='Data Output'!C5 | D5: =ROUND(LET(value,'Data Input'!E5,IF(value>140,value/2,value)),0) -> 71 | E5: ='Data Output'!E5 | F5: ='Data Input'!W5 -> GBAYE0300437
A6: ='Data Input'!C6 -> Harry Nilsson | B6: ='Data Input'!B6 -> Mucho Mungo / Mt. Elga | C6: ='Data Output'!C6 | D6: =ROUND(LET(value,'Data Input'!E6,IF(value>140,value/2,value)),0) -> 116 | E6: ='Data Output'!E6 | F6: ='Data Input'!W6 -> USRC17402438
A7: ='Data Input'!C7 -> Love | B7: ='Data Input'!B7 -> Be Thankful for What You Got | C7: ='Data Output'!C7 | D7: =ROUND(LET(value,'Data Input'!E7,IF(value>140,value/2,value)),0) -> 99 | E7: ='Data Output'!E7 | F7: ='Data Input'!W7 -> QMEF91350058
A8: ='Data Input'!C8 -> Irma Thomas | B8: ='Data Input'!B8 -> Ruler Of My Heart | C8: ='Data Output'!C8 | D8: =ROUND(LET(value,'Data Input'!E8,IF(value>140,value/2,value)),0) -> 94 | E8: ='Data Output'!E8 | F8: ='Data Input'!W8 -> USEM39400180
A9: ='Data Input'!C9 -> J.J. Cale | B9: ='Data Input'!B9 -> Wish I Had Not Said That | C9: ='Data Output'!C9 | D9: =ROUND(LET(value,'Data Input'!E9,IF(value>140,value/2,value)),0) -> 90 | E9: ='Data Output'!E9 | F9: ='Data Input'!W9 -> NLF050290053
A10: ='Data Input'!C10 -> Bill Callahan | B10: ='Data Input'!B10 -> Sycamore | C10: ='Data Output'!C10 | D10: =ROUND(LET(value,'Data Input'!E10,IF(value>140,value/2,value)),0) -> 120 | E10: ='Data Output'!E10 | F10: ='Data Input'!W10 -> US58L0733204
A11: ='Data Input'!C11 -> George Jackson | B11: ='Data Input'!B11 -> Aretha, Sing One for Me | C11: ='Data Output'!C11 | D11: =ROUND(LET(value,'Data Input'!E11,IF(value>140,value/2,value)),0) -> 86 | E11: ='Data Output'!E11 | F11: ='Data Input'!W11 -> US2HK1330630
A12: ='Data Input'!C12 -> Lion | B12: ='Data Input'!B12 -> You've Got a Woman | C12: ='Data Output'!C12 | D12: =ROUND(LET(value,'Data Input'!E12,IF(value>140,value/2,value)),0) -> 72 | E12: ='Data Output'!E12 | F12: ='Data Input'!W12 -> USCW61706301
A13: ='Data Input'!C13 -> Jonathan Richman,The Modern Lovers | B13: ='Data Input'!B13 -> I Love Hot Nights | C13: ='Data Output'!C13 | D13: =ROUND(LET(value,'Data Input'!E13,IF(value>140,value/2,value)),0) -> 112 | E13: ='Data Output'!E13 | F13: ='Data Input'!W13 -> USC4R2111532
... A816: ='Data Input'!C816 | B816: ='Data Input'!B816 | C816: ='Data Output'!C816 | D816: =ROUND(LET(value,'Data Input'!E816,IF(value>140,value/2,value)),0) -> 0 | E816: ='Data Output'!E816 | F816: ='Data Input'!W816

Sheet _TagCache
A1: Artist | B1: Title | C1: Energy Score | D1: Energy Label | E1: Flags | F1: Tagged Date | G1: Actual Energy
A2: FLOOR CRY | B2: Happy Together | C2: 6 | D2: Medium | F2: 45860.724
A3: Dr. Dog | B3: Ladada | C3: 6 | D3: Medium | F3: 45860.724
A4: Loving | B4: Visions | C4: 6 | D4: Medium | F4: 45860.724
A5: Still Woozy | B5: Cooks | C5: 6 | D5: Medium | F5: 45860.724
A6: Mazzy Star | B6: Halah | C6: 3 | D6: Low | F6: 45860.724
A7: DOPE LEMON | B7: Kids Fallin' In Love | C7: 6 | D7: Medium | F7: 45860.724
A8: Marcoca | B8: Floating | C8: 4 | D8: Low | F8: 45860.724
A9: Dream Sitch,Michael Nau,Floating Action | B9: Now On | C9: 5 | D9: Medium | F9: 45860.724
A10: Bob Marley & The Wailers | B10: Could You Be Loved | C10: 7 | D10: High | E10: Dynamic, Groove | F10: 45861.435
A11: Surfaces | B11: Sunday Best | C11: 7 | D11: High | E11: Dynamic, Groove | F11: 45861.435
A12: Harry Styles | B12: Watermelon Sugar | C12: 8 | D12: High | E12: Dynamic, Groove, Anthem | F12: 45861.435
A13: Shawn Mendes,Camila Cabello | B13: Señorita | C13: 8 | D13: High | E13: Dynamic, Groove | F13: 45861.435
A14: Luke Combs | B14: Fast Car | C14: 5 | D14: Medium | F14: 45861.435
A15: TOTO | B15: Africa | C15: 8 | D15: High | E15: Dynamic, Anthem | F15: 45861.435
A16: Train | B16: Hey, Soul Sister | C16: 7 | D16: High | E16: Dynamic, Groove | F16: 45861.435
A17: Toploader | B17: Dancing in the Moonlight | C17: 7 | D17: High | E17: Dynamic, Groove, Anthem | F17: 45861.435
A18: Ed Sheeran & Justin Bieber,Justin Bieber | B18: I Don't Care (with Justin Bieber) | C18: 6 | D18: Medium | E18: Groove | F18: 45861.435
A19: Eagle-Eye Cherry | B19: Save Tonight | C19: 6 | D19: Medium | F19: 45861.436
A20: Tom Petty and the Heartbreakers | B20: American Girl | C20: 8 | D20: High | E20: Dynamic, Anthem | F20: 45861.436
A21: Rusted Root | B21: Send Me On My Way | C21: 8 | D21: High | E21: Dynamic, Groove, Anthem | F21: 45861.436
A22: Kenny Chesney,Uncle Kracker | B22: When the Sun Goes Down | C22: 6 | D22: Medium | F22: 45861.436
A23: Sheppard | B23: Geronimo | C23: 8 | D23: High | E23: Dynamic, Anthem | F23: 45861.436
A24: Morgan Wallen | B24: You Proof | C24: 6 | D24: Medium | F24: 45861.436
A25: Empire Of The Sun | B25: Walking On A Dream | C25: 7 | D25: High | E25: Dynamic, Anthem | F25: 45861.436
A26: Eagles | B26: Take It Easy - 2013 Remaster | C26: 6 | D26: Medium | F26: 45861.436
A27: Avicii | B27: The Days | C27: 8 | D27: High | E27: Dynamic, Anthem | F27: 45861.436
A28: Fitz and The Tantrums | B28: HandClap | C28: 8 | D28: High | E28: Dynamic, Groove, Anthem | F28: 45861.436
A29: Rascal Flatts | B29: Summer Nights | C29: 7 | D29: High | E29: Dynamic, Anthem | F29: 45861.436
A30: Of Monsters and Men | B30: Little Talks | C30: 7 | D30: High | E30: Dynamic, Anthem | F30: 45861.436
A31: Twenty One Pilots | B31: Heathens | C31: 7 | D31: High | E31: Dynamic, Anthem | F31: 45861.436
A32: Andrew McMahon in the Wilderness | B32: Cecilia And The Satellite | C32: 6 | D32: Medium | F32: 45861.436
A33: Morgan Wallen | B33: Whiskey Friends | C33: 5 | D33: Medium | F33: 45861.436
A34: Jordan Davis | B34: Singles You Up | C34: 6 | D34: Medium | F34: 45861.436
A35: BTS | B35: Dynamite | C35: 9 | D35: Very High | E35: Dynamic, Groove, Anthem | F35: 45861.436
A36: SZA | B36: Kill Bill | C36: 5 | D36: Medium | F36: 45861.436
A37: Tyla | B37: Water | C37: 8 | D37: High | E37: Dynamic, Groove, Anthem | F37: 45861.436
A38: Selena Gomez | B38: Love On | C38: 6 | D38: Medium | F38: 45861.436
A39: Luke Combs | B39: When It Rains It Pours | C39: 6 | D39: Medium | F39: 45861.436
A40: Two Door Cinema Club | B40: Sure Enough | C40: 7 | D40: High | E40: Dynamic, Groove | F40: 45861.436
...
